Workbook

Sheet BEHAVIOURABILITY
B1: Decision Making | C1: Self-Management | D1: Communication | E1: Engagement
A2: T1 - Creazione del diario personale <L'utente inserisce all'interno dell'app le proprie preferenze culturali, interessi, hobby e disponibilità temporali, creando una base personalizzata per il sistema.> | B2: K&S | C2: SE | D2: PC | E2: MOT
A3: T2 - Aggiornamento del diario <L'utente modifica nel tempo le proprie preferenze e i propri orari, permettendo al sistema di adattarsi ai cambiamenti del suo stile di vita.> | B3: K&S | C3: SE | D3: PC
A4: T3 - Visualizzazione suggerimenti personalizzati <L'utente consulta gli eventi suggeriti dal sistema, filtrati automaticamente in base ai suoi gusti e alla disponibilità temporale.> | B4: K&S | C4: SE | E4: MOT
A5: T4 - Analisi dettagli evento <L'utente seleziona un evento per visualizzarne i dettagli (luogo, durata, disponibilità, descrizione, distanza).> | B5: K&S | C5: SE | E5: MOT
A6: T5 - Prenotazione evento <L'utente prenota un evento direttamente dall'app in pochi passaggi, senza dover usare piattaforme esterne.> | B6: K&S | C6: SE | D6: PC | E6: MOT
A7: T6 - Sincronizzazione con calendario <L'utente salva l'evento scelto nel proprio calendario personale, integrandolo con i suoi impegni.> | C7: SE | D7: PC | E7: MOT
A8: T7 - Ricezione suggerimenti contestuali <Il sistema propone eventi coerenti con momenti specifici della giornata o della settimana (es. "hai 2 ore libere").> | B8: K&S | C8: SE | D8: PC | E8: MOT
A9: T8 - Gestione notifiche e suggerimenti <L'utente controlla e personalizza il modo in cui riceve suggerimenti (non invasivi, coerenti con il concept del diario).> | C9: SE | D9: PC | E9: MOT

Sheet Quest.Utente1
B1: Self Efficacy | C1: Scarso | D1: Sufficiente | E1: Buono | F1: Molto Buono | G1: Eccellente | H1: Valore
A2: T1_SE1_Creazione | B2: Quanto ti senti capace di inserire i tuoi interessi in modo che il sistema ti capisca perfettamente? | E2: x | H2: =IF(C2="X",1)+IF(D2="X",2)+IF(E2="X",3)+IF(F2="X",4)+IF(G2="X",5) -> 3
A3: T1_SE2_Creazione | B3: Sei sicuro di riuscire a configurare la tua disponibilità oraria senza fare confusione tra i giorni? | G3: x | H3: =IF(C3="X",1)+IF(D3="X",2)+IF(E3="X",3)+IF(F3="X",4)+IF(G3="X",5) -> 5
A4: T1_SE3_Creazione | B4: Quanto ti senti in grado di completare l’intera procedura di setup iniziale senza consultare una guida? | D4: x | H4: =IF(C4="X",1)+IF(D4="X",2)+IF(E4="X",3)+IF(F4="X",4)+IF(G4="X",5) -> 2
B5: Knowledge&Skills
A6: T1_KS1_Creazione | B6: Hai capito quali tipi di hobby e preferenze culturali sono più rilevanti per il sistema? | F6: x | H6: =IF(C6="X",1)+IF(D6="X",2)+IF(E6="X",3)+IF(F6="X",4)+IF(G6="X",5) -> 4
A7: T1_KS2_Creazione | B7: Sai distinguere tra le diverse categorie di interessi messe a disposizione dall'app? | G7: x | H7: =IF(C7="X",1)+IF(D7="X",2)+IF(E7="X",3)+IF(F7="X",4)+IF(G7="X",5) -> 5
A8: T1_KS3_Creazione | B8: Conosci la differenza tra inserire un interesse generico e uno specifico in questa fase? | E8: x | H8: =IF(C8="X",1)+IF(D8="X",2)+IF(E8="X",3)+IF(F8="X",4)+IF(G8="X",5) -> 3
B9: Personal Control
A10: T1_PC1_Creazione | B10: Senti di poter decidere liberamente quali aspetti della tua vita privata omettere dal diario? | G10: x | H10: =IF(C10="X",1)+IF(D10="X",2)+IF(E10="X",3)+IF(F10="X",4)+IF(G10="X",5) -> 5
A11: T1_PC2_Creazione | B11: Ti senti padrone della scelta di quanto tempo dedicare a questa configurazione iniziale? | F11: x | H11: =IF(C11="X",1)+IF(D11="X",2)+IF(E11="X",3)+IF(F11="X",4)+IF(G11="X",5) -> 4
B12: Motivation
A13: T1_MOT1_Creazione | B13: Quanto ti stimola l'idea che, compilando il diario, l'app diventerà uno specchio dei tuoi gusti? | G13: x | H13: =IF(C13="X",1)+IF(D13="X",2)+IF(E13="X",3)+IF(F13="X",4)+IF(G13="X",5) -> 5
A14: T1_MOT1_Creazione | B14: Sei spinto a inserire più dettagli possibili per ottenere suggerimenti di alta qualità? | G14: x | H14: =IF(C14="X",1)+IF(D14="X",2)+IF(E14="X",3)+IF(F14="X",4)+IF(G14="X",5) -> 5
B15: Self Efficacy
A16: T2_SE1_Aggiornamento | B16: Quanto ti senti sicuro di poter modificare i tuoi orari quando il tuo stile di vita cambia? | D16: x | H16: =IF(C16="X",1)+IF(D16="X",2)+IF(E16="X",3)+IF(F16="X",4)+IF(G16="X",5) -> 2
A17: T2_SE2_Aggiornamento | B17: Ti senti in grado di eliminare un vecchio interesse che non ti appartiene più in pochi secondi? | C17: x | H17: =IF(C17="X",1)+IF(D17="X",2)+IF(E17="X",3)+IF(F17="X",4)+IF(G17="X",5) -> 1
A18: T2_SE3_Aggiornamento | B18: Sei certo di riuscire a mantenere il diario aggiornato anche se hai poco tempo a disposizione? | F18: x | H18: =IF(C18="X",1)+IF(D18="X",2)+IF(E18="X",3)+IF(F18="X",4)+IF(G18="X",5) -> 4
B19: Knowledge&Skills
A20: T2_KS1_Aggiornamento | B20: Sai in quale sezione del profilo devi recarti per modificare la tua disponibilità settimanale? | F20: x | H20: =IF(C20="X",1)+IF(D20="X",2)+IF(E20="X",3)+IF(F20="X",4)+IF(G20="X",5) -> 4
A21: T2_KS2_Aggiornamento | B21: Hai compreso come le modifiche che apporti oggi influenzeranno i suggerimenti di domani? | F21: x | H21: =IF(C21="X",1)+IF(D21="X",2)+IF(E21="X",3)+IF(F21="X",4)+IF(G21="X",5) -> 4
A22: T2_KS3_Aggiornamento | B22: Conosci la procedura per salvare correttamente i cambiamenti apportati alle preferenze? | E22: x | H22: =IF(C22="X",1)+IF(D22="X",2)+IF(E22="X",3)+IF(F22="X",4)+IF(G22="X",5) -> 3
B23: Personal Control
A24: T2_PC1_Aggiornamento | B24: Senti di avere il controllo totale sulla frequenza con cui puoi cambiare i tuoi dati? | G24: x | H24: =IF(C24="X",1)+IF(D24="X",2)+IF(E24="X",3)+IF(F24="X",4)+IF(G24="X",5) -> 5
A25: T2_PC2_Aggiornamento | B25: Ti senti libero di resettare completamente le tue preferenze se decidi di cambiare interessi? | D25: x | H25: =IF(C25="X",1)+IF(D25="X",2)+IF(E25="X",3)+IF(F25="X",4)+IF(G25="X",5) -> 2
B26: Self Efficacy | C26: Scarso | D26: Sufficiente | E26: Buono | F26: Molto Buono | G26: Eccellente | H26: Valore
A27: T3_SE1_Visualizzazione | B27: Quanto ti senti capace di individuare rapidamente l'evento perfetto tra quelli proposti? | F27: x | H27: =IF(C27="X",1)+IF(D27="X",2)+IF(E27="X",3)+IF(F27="X",4)+IF(G27="X",5) -> 4
A28: T3_SE2_Visualizzazione | B28: Sei sicuro di saper navigare tra i vari suggerimenti senza sentirti sopraffatto? | E28: X | H28: =IF(C28="X",1)+IF(D28="X",2)+IF(E28="X",3)+IF(F28="X",4)+IF(G28="X",5) -> 3
A29: T3_SE3_Visualizzazione | B29: Ti senti in grado di interpretare correttamente i simboli che indicano la compatibilità con i tuoi gusti? | F29: x | H29: =IF(C29="X",1)+IF(D29="X",2)+IF(E29="X",3)+IF(F29="X",4)+IF(G29="X",5) -> 4
B30: Knowledge&Skills
A31: T3_KS1_Visualizzazione | B31: Sai come vengono ordinati i suggerimenti che vedi sulla schermata principale? | G31: x | H31: =IF(C31="X",1)+IF(D31="X",2)+IF(E31="X",3)+IF(F31="X",4)+IF(G31="X",5) -> 5
A32: T3_KS2_Visualizzazione | B32: Hai capito perché alcuni eventi appaiono come "prioritari" rispetto ad altri? | F32: x | H32: =IF(C32="X",1)+IF(D32="X",2)+IF(E32="X",3)+IF(F32="X",4)+IF(G32="X",5) -> 4
A33: T3_KS3_Visualizzazione | B33: Conosci il significato dei tag di categorizzazione associati a ogni suggerimento? | G33: x | H33: =IF(C33="X",1)+IF(D33="X",2)+IF(E33="X",3)+IF(F33="X",4)+IF(G33="X",5) -> 5
B34: Motivation
A35: T3_MOT1_Visualizzazione | B35: Quanto ti entusiasma scoprire attività nuove che non avresti mai cercato da solo? | G35: x | H35: =IF(C35="X",1)+IF(D35="X",2)+IF(E35="X",3)+IF(F35="X",4)+IF(G35="X",5) -> 5
A36: T3_MOT1_Visualizzazione | B36: Ti senti spronato a usare l'app ogni mattina per vedere cosa ha selezionato per te? | F36: x | H36: =IF(C36="X",1)+IF(D36="X",2)+IF(E36="X",3)+IF(F36="X",4)+IF(G36="X",5) -> 4
B37: Self Efficacy | C37: Scarso | D37: Sufficiente | E37: Buono | F37: Molto Buono | G37: Eccellente | H37: Valore
A38: T4_SE1_Analisi | B38: Quanto ti senti sicuro nel valutare se un evento è raggiungibile in tempo basandoti sulla distanza indicata? | F38: x | H38: =IF(C38="X",1)+IF(D38="X",2)+IF(E38="X",3)+IF(F38="X",4)+IF(G38="X",5) -> 4
A39: T4_SE2_Analisi | B39: Ti senti in grado di capire se un evento è adatto al tuo budget leggendo i dettagli? | E39: x | H39: =IF(C39="X",1)+IF(D39="X",2)+IF(E39="X",3)+IF(F39="X",4)+IF(G39="X",5) -> 3
A40: T4_SE3_Analisi | B40: Sei certo di poter decidere se partecipare a un evento dopo aver letto la sua descrizione tecnica? | F40: x | H40: =IF(C40="X",1)+IF(D40="X",2)+IF(E40="X",3)+IF(F40="X",4)+IF(G40="X",5) -> 4
...

Sheet Quest.Utente2
B1: Self Efficacy | C1: Scarso | D1: Sufficiente | E1: Buono | F1: Molto Buono | G1: Eccellente | H1: Valore
A2: T1_SE1_Creazione | B2: Quanto ti senti capace di inserire i tuoi interessi in modo che il sistema ti capisca perfettamente? | F2: x | H2: =IF(C2="X",1)+IF(D2="X",2)+IF(E2="X",3)+IF(F2="X",4)+IF(G2="X",5) -> 4
A3: T1_SE2_Creazione | B3: Sei sicuro di riuscire a configurare la tua disponibilità oraria senza fare confusione tra i giorni? | E3: x | H3: =IF(C3="X",1)+IF(D3="X",2)+IF(E3="X",3)+IF(F3="X",4)+IF(G3="X",5) -> 3
A4: T1_SE3_Creazione | B4: Quanto ti senti in grado di completare l’intera procedura di setup iniziale senza consultare una guida? | G4: x | H4: =IF(C4="X",1)+IF(D4="X",2)+IF(E4="X",3)+IF(F4="X",4)+IF(G4="X",5) -> 5
B5: Knowledge&Skills
A6: T1_KS1_Creazione | B6: Hai capito quali tipi di hobby e preferenze culturali sono più rilevanti per il sistema? | D6: x | H6: =IF(C6="X",1)+IF(D6="X",2)+IF(E6="X",3)+IF(F6="X",4)+IF(G6="X",5) -> 2
A7: T1_KS2_Creazione | B7: Sai distinguere tra le diverse categorie di interessi messe a disposizione dall'app? | D7: x | H7: =IF(C7="X",1)+IF(D7="X",2)+IF(E7="X",3)+IF(F7="X",4)+IF(G7="X",5) -> 2
A8: T1_KS3_Creazione | B8: Conosci la differenza tra inserire un interesse generico e uno specifico in questa fase? | E8: x | H8: =IF(C8="X",1)+IF(D8="X",2)+IF(E8="X",3)+IF(F8="X",4)+IF(G8="X",5) -> 3
B9: Personal Control
A10: T1_PC1_Creazione | B10: Senti di poter decidere liberamente quali aspetti della tua vita privata omettere dal diario? | E10: x | H10: =IF(C10="X",1)+IF(D10="X",2)+IF(E10="X",3)+IF(F10="X",4)+IF(G10="X",5) -> 3
A11: T1_PC2_Creazione | B11: Ti senti padrone della scelta di quanto tempo dedicare a questa configurazione iniziale? | G11: x | H11: =IF(C11="X",1)+IF(D11="X",2)+IF(E11="X",3)+IF(F11="X",4)+IF(G11="X",5) -> 5
B12: Motivation
A13: T1_MOT1_Creazione | B13: Quanto ti stimola l'idea che, compilando il diario, l'app diventerà uno specchio dei tuoi gusti? | E13: x | H13: =IF(C13="X",1)+IF(D13="X",2)+IF(E13="X",3)+IF(F13="X",4)+IF(G13="X",5) -> 3
A14: T1_MOT1_Creazione | B14: Sei spinto a inserire più dettagli possibili per ottenere suggerimenti di alta qualità? | D14: x | H14: =IF(C14="X",1)+IF(D14="X",2)+IF(E14="X",3)+IF(F14="X",4)+IF(G14="X",5) -> 2
B15: Self Efficacy
A16: T2_SE1_Aggiornamento | B16: Quanto ti senti sicuro di poter modificare i tuoi orari quando il tuo stile di vita cambia? | G16: x | H16: =IF(C16="X",1)+IF(D16="X",2)+IF(E16="X",3)+IF(F16="X",4)+IF(G16="X",5) -> 5
A17: T2_SE2_Aggiornamento | B17: Ti senti in grado di eliminare un vecchio interesse che non ti appartiene più in pochi secondi? | D17: x | H17: =IF(C17="X",1)+IF(D17="X",2)+IF(E17="X",3)+IF(F17="X",4)+IF(G17="X",5) -> 2
A18: T2_SE3_Aggiornamento | B18: Sei certo di riuscire a mantenere il diario aggiornato anche se hai poco tempo a disposizione? | F18: x | H18: =IF(C18="X",1)+IF(D18="X",2)+IF(E18="X",3)+IF(F18="X",4)+IF(G18="X",5) -> 4
B19: Knowledge&Skills
A20: T2_KS1_Aggiornamento | B20: Sai in quale sezione del profilo devi recarti per modificare la tua disponibilità settimanale? | D20: x | H20: =IF(C20="X",1)+IF(D20="X",2)+IF(E20="X",3)+IF(F20="X",4)+IF(G20="X",5) -> 2
A21: T2_KS2_Aggiornamento | B21: Hai compreso come le modifiche che apporti oggi influenzeranno i suggerimenti di domani? | G21: x | H21: =IF(C21="X",1)+IF(D21="X",2)+IF(E21="X",3)+IF(F21="X",4)+IF(G21="X",5) -> 5
A22: T2_KS3_Aggiornamento | B22: Conosci la procedura per salvare correttamente i cambiamenti apportati alle preferenze? | G22: x | H22: =IF(C22="X",1)+IF(D22="X",2)+IF(E22="X",3)+IF(F22="X",4)+IF(G22="X",5) -> 5
B23: Personal Control
A24: T2_PC1_Aggiornamento | B24: Senti di avere il controllo totale sulla frequenza con cui puoi cambiare i tuoi dati? | E24: x | H24: =IF(C24="X",1)+IF(D24="X",2)+IF(E24="X",3)+IF(F24="X",4)+IF(G24="X",5) -> 3
A25: T2_PC2_Aggiornamento | B25: Ti senti libero di resettare completamente le tue preferenze se decidi di cambiare interessi? | E25: x | H25: =IF(C25="X",1)+IF(D25="X",2)+IF(E25="X",3)+IF(F25="X",4)+IF(G25="X",5) -> 3
B26: Self Efficacy | C26: Scarso | D26: Sufficiente | E26: Buono | F26: Molto Buono | G26: Eccellente | H26: Valore
A27: T3_SE1_Visualizzazione | B27: Quanto ti senti capace di individuare rapidamente l'evento perfetto tra quelli proposti? | C27: x | H27: =IF(C27="X",1)+IF(D27="X",2)+IF(E27="X",3)+IF(F27="X",4)+IF(G27="X",5) -> 1
A28: T3_SE2_Visualizzazione | B28: Sei sicuro di saper navigare tra i vari suggerimenti senza sentirti sopraffatto? | D28: x | H28: =IF(C28="X",1)+IF(D28="X",2)+IF(E28="X",3)+IF(F28="X",4)+IF(G28="X",5) -> 2
A29: T3_SE3_Visualizzazione | B29: Ti senti in grado di interpretare correttamente i simboli che indicano la compatibilità con i tuoi gusti? | E29: x | H29: =IF(C29="X",1)+IF(D29="X",2)+IF(E29="X",3)+IF(F29="X",4)+IF(G29="X",5) -> 3
B30: Knowledge&Skills
A31: T3_KS1_Visualizzazione | B31: Sai come vengono ordinati i suggerimenti che vedi sulla schermata principale? | D31: x | H31: =IF(C31="X",1)+IF(D31="X",2)+IF(E31="X",3)+IF(F31="X",4)+IF(G31="X",5) -> 2
A32: T3_KS2_Visualizzazione | B32: Hai capito perché alcuni eventi appaiono come "prioritari" rispetto ad altri? | D32: x | H32: =IF(C32="X",1)+IF(D32="X",2)+IF(E32="X",3)+IF(F32="X",4)+IF(G32="X",5) -> 2
A33: T3_KS3_Visualizzazione | B33: Conosci il significato dei tag di categorizzazione associati a ogni suggerimento? | E33: x | H33: =IF(C33="X",1)+IF(D33="X",2)+IF(E33="X",3)+IF(F33="X",4)+IF(G33="X",5) -> 3
B34: Motivation
A35: T3_MOT1_Visualizzazione | B35: Quanto ti entusiasma scoprire attività nuove che non avresti mai cercato da solo? | G35: x | H35: =IF(C35="X",1)+IF(D35="X",2)+IF(E35="X",3)+IF(F35="X",4)+IF(G35="X",5) -> 5
A36: T3_MOT1_Visualizzazione | B36: Ti senti spronato a usare l'app ogni mattina per vedere cosa ha selezionato per te? | E36: x | H36: =IF(C36="X",1)+IF(D36="X",2)+IF(E36="X",3)+IF(F36="X",4)+IF(G36="X",5) -> 3
B37: Self Efficacy | C37: Scarso | D37: Sufficiente | E37: Buono | F37: Molto Buono | G37: Eccellente | H37: Valore
A38: T4_SE1_Analisi | B38: Quanto ti senti sicuro nel valutare se un evento è raggiungibile in tempo basandoti sulla distanza indicata? | G38: x | H38: =IF(C38="X",1)+IF(D38="X",2)+IF(E38="X",3)+IF(F38="X",4)+IF(G38="X",5) -> 5
A39: T4_SE2_Analisi | B39: Ti senti in grado di capire se un evento è adatto al tuo budget leggendo i dettagli? | F39: x | H39: =IF(C39="X",1)+IF(D39="X",2)+IF(E39="X",3)+IF(F39="X",4)+IF(G39="X",5) -> 4
A40: T4_SE3_Analisi | B40: Sei certo di poter decidere se partecipare a un evento dopo aver letto la sua descrizione tecnica? | G40: x | H40: =IF(C40="X",1)+IF(D40="X",2)+IF(E40="X",3)+IF(F40="X",4)+IF(G40="X",5) -> 5
...

Sheet Quest.Utente3
B1: Self Efficacy | C1: Scarso | D1: Sufficiente | E1: Buono | F1: Molto Buono | G1: Eccellente | H1: Valore
A2: T1_SE1_Creazione | B2: Quanto ti senti capace di inserire i tuoi interessi in modo che il sistema ti capisca perfettamente? | D2: x | H2: =IF(C2="X",1)+IF(D2="X",2)+IF(E2="X",3)+IF(F2="X",4)+IF(G2="X",5) -> 2
A3: T1_SE2_Creazione | B3: Sei sicuro di riuscire a configurare la tua disponibilità oraria senza fare confusione tra i giorni? | E3: x | H3: =IF(C3="X",1)+IF(D3="X",2)+IF(E3="X",3)+IF(F3="X",4)+IF(G3="X",5) -> 3
A4: T1_SE3_Creazione | B4: Quanto ti senti in grado di completare l’intera procedura di setup iniziale senza consultare una guida? | D4: x | H4: =IF(C4="X",1)+IF(D4="X",2)+IF(E4="X",3)+IF(F4="X",4)+IF(G4="X",5) -> 2
B5: Knowledge&Skills
A6: T1_KS1_Creazione | B6: Hai capito quali tipi di hobby e preferenze culturali sono più rilevanti per il sistema? | E6: x | H6: =IF(C6="X",1)+IF(D6="X",2)+IF(E6="X",3)+IF(F6="X",4)+IF(G6="X",5) -> 3
A7: T1_KS2_Creazione | B7: Sai distinguere tra le diverse categorie di interessi messe a disposizione dall'app? | C7: x | H7: =IF(C7="X",1)+IF(D7="X",2)+IF(E7="X",3)+IF(F7="X",4)+IF(G7="X",5) -> 1
A8: T1_KS3_Creazione | B8: Conosci la differenza tra inserire un interesse generico e uno specifico in questa fase? | E8: x | H8: =IF(C8="X",1)+IF(D8="X",2)+IF(E8="X",3)+IF(F8="X",4)+IF(G8="X",5) -> 3
B9: Personal Control
A10: T1_PC1_Creazione | B10: Senti di poter decidere liberamente quali aspetti della tua vita privata omettere dal diario? | E10: x | H10: =IF(C10="X",1)+IF(D10="X",2)+IF(E10="X",3)+IF(F10="X",4)+IF(G10="X",5) -> 3
A11: T1_PC2_Creazione | B11: Ti senti padrone della scelta di quanto tempo dedicare a questa configurazione iniziale? | G11: x | H11: =IF(C11="X",1)+IF(D11="X",2)+IF(E11="X",3)+IF(F11="X",4)+IF(G11="X",5) -> 5
B12: Motivation
A13: T1_MOT1_Creazione | B13: Quanto ti stimola l'idea che, compilando il diario, l'app diventerà uno specchio dei tuoi gusti? | G13: x | H13: =IF(C13="X",1)+IF(D13="X",2)+IF(E13="X",3)+IF(F13="X",4)+IF(G13="X",5) -> 5
A14: T1_MOT1_Creazione | B14: Sei spinto a inserire più dettagli possibili per ottenere suggerimenti di alta qualità? | F14: x | H14: =IF(C14="X",1)+IF(D14="X",2)+IF(E14="X",3)+IF(F14="X",4)+IF(G14="X",5) -> 4
B15: Self Efficacy | C15: Scarso | D15: Sufficiente | E15: Buono | F15: Molto Buono | G15: Eccellente | H15: Valore
A16: T2_SE1_Aggiornamento | B16: Quanto ti senti sicuro di poter modificare i tuoi orari quando il tuo stile di vita cambia? | C16: x | H16: =IF(C16="X",1)+IF(D16="X",2)+IF(E16="X",3)+IF(F16="X",4)+IF(G16="X",5) -> 1
A17: T2_SE2_Aggiornamento | B17: Ti senti in grado di eliminare un vecchio interesse che non ti appartiene più in pochi secondi? | E17: x | H17: =IF(C17="X",1)+IF(D17="X",2)+IF(E17="X",3)+IF(F17="X",4)+IF(G17="X",5) -> 3
A18: T2_SE3_Aggiornamento | B18: Sei certo di riuscire a mantenere il diario aggiornato anche se hai poco tempo a disposizione? | E18: x | H18: =IF(C18="X",1)+IF(D18="X",2)+IF(E18="X",3)+IF(F18="X",4)+IF(G18="X",5) -> 3
B19: Knowledge&Skills
A20: T2_KS1_Aggiornamento | B20: Sai in quale sezione del profilo devi recarti per modificare la tua disponibilità settimanale? | D20: x | H20: =IF(C20="X",1)+IF(D20="X",2)+IF(E20="X",3)+IF(F20="X",4)+IF(G20="X",5) -> 2
A21: T2_KS2_Aggiornamento | B21: Hai compreso come le modifiche che apporti oggi influenzeranno i suggerimenti di domani? | E21: x | H21: =IF(C21="X",1)+IF(D21="X",2)+IF(E21="X",3)+IF(F21="X",4)+IF(G21="X",5) -> 3
A22: T2_KS3_Aggiornamento | B22: Conosci la procedura per salvare correttamente i cambiamenti apportati alle preferenze? | E22: x | H22: =IF(C22="X",1)+IF(D22="X",2)+IF(E22="X",3)+IF(F22="X",4)+IF(G22="X",5) -> 3
B23: Personal Control
A24: T2_PC1_Aggiornamento | B24: Senti di avere il controllo totale sulla frequenza con cui puoi cambiare i tuoi dati? | D24: x | H24: =IF(C24="X",1)+IF(D24="X",2)+IF(E24="X",3)+IF(F24="X",4)+IF(G24="X",5) -> 2
A25: T2_PC2_Aggiornamento | B25: Ti senti libero di resettare completamente le tue preferenze se decidi di cambiare interessi? | C25: x | H25: =IF(C25="X",1)+IF(D25="X",2)+IF(E25="X",3)+IF(F25="X",4)+IF(G25="X",5) -> 1
B26: Self Efficacy | C26: Scarso | D26: Sufficiente | E26: Buono | F26: Molto Buono | G26: Eccellente | H26: Valore
A27: T3_SE1_Visualizzazione | B27: Quanto ti senti capace di individuare rapidamente l'evento perfetto tra quelli proposti? | D27: x | H27: =IF(C27="X",1)+IF(D27="X",2)+IF(E27="X",3)+IF(F27="X",4)+IF(G27="X",5) -> 2
A28: T3_SE2_Visualizzazione | B28: Sei sicuro di saper navigare tra i vari suggerimenti senza sentirti sopraffatto? | C28: x | H28: =IF(C28="X",1)+IF(D28="X",2)+IF(E28="X",3)+IF(F28="X",4)+IF(G28="X",5) -> 1
A29: T3_SE3_Visualizzazione | B29: Ti senti in grado di interpretare correttamente i simboli che indicano la compatibilità con i tuoi gusti? | E29: x | H29: =IF(C29="X",1)+IF(D29="X",2)+IF(E29="X",3)+IF(F29="X",4)+IF(G29="X",5) -> 3
B30: Knowledge&Skills
A31: T3_KS1_Visualizzazione | B31: Sai come vengono ordinati i suggerimenti che vedi sulla schermata principale? | D31: x | H31: =IF(C31="X",1)+IF(D31="X",2)+IF(E31="X",3)+IF(F31="X",4)+IF(G31="X",5) -> 2
A32: T3_KS2_Visualizzazione | B32: Hai capito perché alcuni eventi appaiono come "prioritari" rispetto ad altri? | C32: x | H32: =IF(C32="X",1)+IF(D32="X",2)+IF(E32="X",3)+IF(F32="X",4)+IF(G32="X",5) -> 1
A33: T3_KS3_Visualizzazione | B33: Conosci il significato dei tag di categorizzazione associati a ogni suggerimento? | D33: x | H33: =IF(C33="X",1)+IF(D33="X",2)+IF(E33="X",3)+IF(F33="X",4)+IF(G33="X",5) -> 2
B34: Motivation
A35: T3_MOT1_Visualizzazione | B35: Quanto ti entusiasma scoprire attività nuove che non avresti mai cercato da solo? | G35: x | H35: =IF(C35="X",1)+IF(D35="X",2)+IF(E35="X",3)+IF(F35="X",4)+IF(G35="X",5) -> 5
A36: T3_MOT1_Visualizzazione | B36: Ti senti spronato a usare l'app ogni mattina per vedere cosa ha selezionato per te? | G36: x | H36: =IF(C36="X",1)+IF(D36="X",2)+IF(E36="X",3)+IF(F36="X",4)+IF(G36="X",5) -> 5
B37: Self Efficacy | C37: Scarso | D37: Sufficiente | E37: Buono | F37: Molto Buono | G37: Eccellente | H37: Valore
A38: T4_SE1_Analisi | B38: Quanto ti senti sicuro nel valutare se un evento è raggiungibile in tempo basandoti sulla distanza indicata? | E38: x | H38: =IF(C38="X",1)+IF(D38="X",2)+IF(E38="X",3)+IF(F38="X",4)+IF(G38="X",5) -> 3
A39: T4_SE2_Analisi | B39: Ti senti in grado di capire se un evento è adatto al tuo budget leggendo i dettagli? | F39: x | H39: =IF(C39="X",1)+IF(D39="X",2)+IF(E39="X",3)+IF(F39="X",4)+IF(G39="X",5) -> 4
A40: T4_SE3_Analisi | B40: Sei certo di poter decidere se partecipare a un evento dopo aver letto la sua descrizione tecnica? | F40: x | H40: =IF(C40="X",1)+IF(D40="X",2)+IF(E40="X",3)+IF(F40="X",4)+IF(G40="X",5) -> 4
...

Sheet Quest.Utente4
B1: Self Efficacy | C1: Scarso | D1: Sufficiente | E1: Buono | F1: Molto Buono | G1: Eccellente | H1: Valore
A2: T1_SE1_Creazione | B2: Quanto ti senti capace di inserire i tuoi interessi in modo che il sistema ti capisca perfettamente? | E2: x | H2: =IF(C2="X",1)+IF(D2="X",2)+IF(E2="X",3)+IF(F2="X",4)+IF(G2="X",5) -> 3
A3: T1_SE2_Creazione | B3: Sei sicuro di riuscire a configurare la tua disponibilità oraria senza fare confusione tra i giorni? | E3: x | H3: =IF(C3="X",1)+IF(D3="X",2)+IF(E3="X",3)+IF(F3="X",4)+IF(G3="X",5) -> 3
A4: T1_SE3_Creazione | B4: Quanto ti senti in grado di completare l’intera procedura di setup iniziale senza consultare una guida? | G4: x | H4: =IF(C4="X",1)+IF(D4="X",2)+IF(E4="X",3)+IF(F4="X",4)+IF(G4="X",5) -> 5
B5: Knowledge&Skills
A6: T1_KS1_Creazione | B6: Hai capito quali tipi di hobby e preferenze culturali sono più rilevanti per il sistema? | F6: x | H6: =IF(C6="X",1)+IF(D6="X",2)+IF(E6="X",3)+IF(F6="X",4)+IF(G6="X",5) -> 4
A7: T1_KS2_Creazione | B7: Sai distinguere tra le diverse categorie di interessi messe a disposizione dall'app? | E7: x | H7: =IF(C7="X",1)+IF(D7="X",2)+IF(E7="X",3)+IF(F7="X",4)+IF(G7="X",5) -> 3
A8: T1_KS3_Creazione | B8: Conosci la differenza tra inserire un interesse generico e uno specifico in questa fase? | E8: x | H8: =IF(C8="X",1)+IF(D8="X",2)+IF(E8="X",3)+IF(F8="X",4)+IF(G8="X",5) -> 3
B9: Personal Control
A10: T1_PC1_Creazione | B10: Senti di poter decidere liberamente quali aspetti della tua vita privata omettere dal diario? | E10: x | H10: =IF(C10="X",1)+IF(D10="X",2)+IF(E10="X",3)+IF(F10="X",4)+IF(G10="X",5) -> 3
A11: T1_PC2_Creazione | B11: Ti senti padrone della scelta di quanto tempo dedicare a questa configurazione iniziale? | G11: x | H11: =IF(C11="X",1)+IF(D11="X",2)+IF(E11="X",3)+IF(F11="X",4)+IF(G11="X",5) -> 5
B12: Motivation
A13: T1_MOT1_Creazione | B13: Quanto ti stimola l'idea che, compilando il diario, l'app diventerà uno specchio dei tuoi gusti? | E13: x | H13: =IF(C13="X",1)+IF(D13="X",2)+IF(E13="X",3)+IF(F13="X",4)+IF(G13="X",5) -> 3
A14: T1_MOT1_Creazione | B14: Sei spinto a inserire più dettagli possibili per ottenere suggerimenti di alta qualità? | D14: x | H14: =IF(C14="X",1)+IF(D14="X",2)+IF(E14="X",3)+IF(F14="X",4)+IF(G14="X",5) -> 2
B15: Self Efficacy
A16: T2_SE1_Aggiornamento | B16: Quanto ti senti sicuro di poter modificare i tuoi orari quando il tuo stile di vita cambia? | G16: x | H16: =IF(C16="X",1)+IF(D16="X",2)+IF(E16="X",3)+IF(F16="X",4)+IF(G16="X",5) -> 5
A17: T2_SE2_Aggiornamento | B17: Ti senti in grado di eliminare un vecchio interesse che non ti appartiene più in pochi secondi? | D17: x | H17: =IF(C17="X",1)+IF(D17="X",2)+IF(E17="X",3)+IF(F17="X",4)+IF(G17="X",5) -> 2
A18: T2_SE3_Aggiornamento | B18: Sei certo di riuscire a mantenere il diario aggiornato anche se hai poco tempo a disposizione? | E18: x | H18: =IF(C18="X",1)+IF(D18="X",2)+IF(E18="X",3)+IF(F18="X",4)+IF(G18="X",5) -> 3
B19: Knowledge&Skills
A20: T2_KS1_Aggiornamento | B20: Sai in quale sezione del profilo devi recarti per modificare la tua disponibilità settimanale? | D20: x | H20: =IF(C20="X",1)+IF(D20="X",2)+IF(E20="X",3)+IF(F20="X",4)+IF(G20="X",5) -> 2
A21: T2_KS2_Aggiornamento | B21: Hai compreso come le modifiche che apporti oggi influenzeranno i suggerimenti di domani? | F21: x | H21: =IF(C21="X",1)+IF(D21="X",2)+IF(E21="X",3)+IF(F21="X",4)+IF(G21="X",5) -> 4
A22: T2_KS3_Aggiornamento | B22: Conosci la procedura per salvare correttamente i cambiamenti apportati alle preferenze? | G22: x | H22: =IF(C22="X",1)+IF(D22="X",2)+IF(E22="X",3)+IF(F22="X",4)+IF(G22="X",5) -> 5
B23: Personal Control
A24: T2_PC1_Aggiornamento | B24: Senti di avere il controllo totale sulla frequenza con cui puoi cambiare i tuoi dati? | E24: x | H24: =IF(C24="X",1)+IF(D24="X",2)+IF(E24="X",3)+IF(F24="X",4)+IF(G24="X",5) -> 3
A25: T2_PC2_Aggiornamento | B25: Ti senti libero di resettare completamente le tue preferenze se decidi di cambiare interessi? | D25: x | H25: =IF(C25="X",1)+IF(D25="X",2)+IF(E25="X",3)+IF(F25="X",4)+IF(G25="X",5) -> 2
B26: Self Efficacy | C26: Scarso | D26: Sufficiente | E26: Buono | F26: Molto Buono | G26: Eccellente | H26: Valore
A27: T3_SE1_Visualizzazione | B27: Quanto ti senti capace di individuare rapidamente l'evento perfetto tra quelli proposti? | F27: x | H27: =IF(C27="X",1)+IF(D27="X",2)+IF(E27="X",3)+IF(F27="X",4)+IF(G27="X",5) -> 4
A28: T3_SE2_Visualizzazione | B28: Sei sicuro di saper navigare tra i vari suggerimenti senza sentirti sopraffatto? | F28: x | H28: =IF(C28="X",1)+IF(D28="X",2)+IF(E28="X",3)+IF(F28="X",4)+IF(G28="X",5) -> 4
A29: T3_SE3_Visualizzazione | B29: Ti senti in grado di interpretare correttamente i simboli che indicano la compatibilità con i tuoi gusti? | E29: x | H29: =IF(C29="X",1)+IF(D29="X",2)+IF(E29="X",3)+IF(F29="X",4)+IF(G29="X",5) -> 3
B30: Knowledge&Skills
A31: T3_KS1_Visualizzazione | B31: Sai come vengono ordinati i suggerimenti che vedi sulla schermata principale? | F31: x | H31: =IF(C31="X",1)+IF(D31="X",2)+IF(E31="X",3)+IF(F31="X",4)+IF(G31="X",5) -> 4
A32: T3_KS2_Visualizzazione | B32: Hai capito perché alcuni eventi appaiono come "prioritari" rispetto ad altri? | C32: x | H32: =IF(C32="X",1)+IF(D32="X",2)+IF(E32="X",3)+IF(F32="X",4)+IF(G32="X",5) -> 1
A33: T3_KS3_Visualizzazione | B33: Conosci il significato dei tag di categorizzazione associati a ogni suggerimento? | E33: x | H33: =IF(C33="X",1)+IF(D33="X",2)+IF(E33="X",3)+IF(F33="X",4)+IF(G33="X",5) -> 3
B34: Motivation
A35: T3_MOT1_Visualizzazione | B35: Quanto ti entusiasma scoprire attività nuove che non avresti mai cercato da solo? | G35: x | H35: =IF(C35="X",1)+IF(D35="X",2)+IF(E35="X",3)+IF(F35="X",4)+IF(G35="X",5) -> 5
A36: T3_MOT1_Visualizzazione | B36: Ti senti spronato a usare l'app ogni mattina per vedere cosa ha selezionato per te? | E36: x | H36: =IF(C36="X",1)+IF(D36="X",2)+IF(E36="X",3)+IF(F36="X",4)+IF(G36="X",5) -> 3
B37: Self Efficacy | C37: Scarso | D37: Sufficiente | E37: Buono | F37: Molto Buono | G37: Eccellente | H37: Valore
A38: T4_SE1_Analisi | B38: Quanto ti senti sicuro nel valutare se un evento è raggiungibile in tempo basandoti sulla distanza indicata? | G38: x | H38: =IF(C38="X",1)+IF(D38="X",2)+IF(E38="X",3)+IF(F38="X",4)+IF(G38="X",5) -> 5
A39: T4_SE2_Analisi | B39: Ti senti in grado di capire se un evento è adatto al tuo budget leggendo i dettagli? | E39: x | H39: =IF(C39="X",1)+IF(D39="X",2)+IF(E39="X",3)+IF(F39="X",4)+IF(G39="X",5) -> 3
A40: T4_SE3_Analisi | B40: Sei certo di poter decidere se partecipare a un evento dopo aver letto la sua descrizione tecnica? | G40: x | H40: =IF(C40="X",1)+IF(D40="X",2)+IF(E40="X",3)+IF(F40="X",4)+IF(G40="X",5) -> 5
...

Sheet MEDIE
B1: Self Efficacy | C1: Valore
A2: T1_SE1_Creazione | B2: Quanto ti senti capace di inserire i tuoi interessi in modo che il sistema ti capisca perfettamente? | C2: =AVERAGE(Quest.Utente1!H2,Quest.Utente2!H2,Quest.Utente3!H2,Quest.Utente4!H2) -> 3
A3: T1_SE2_Creazione | B3: Sei sicuro di riuscire a configurare la tua disponibilità oraria senza fare confusione tra i giorni? | C3: =AVERAGE(Quest.Utente1!H3,Quest.Utente2!H3,Quest.Utente3!H3,Quest.Utente4!H3) -> 3.5
A4: T1_SE3_Creazione | B4: Quanto ti senti in grado di completare l’intera procedura di setup iniziale senza consultare una guida? | C4: =AVERAGE(Quest.Utente1!H4,Quest.Utente2!H4,Quest.Utente3!H4,Quest.Utente4!H4) -> 3.5
B5: Knowledge&Skills
A6: T1_KS1_Creazione | B6: Hai capito quali tipi di hobby e preferenze culturali sono più rilevanti per il sistema? | C6: =AVERAGE(Quest.Utente1!H6,Quest.Utente2!H6,Quest.Utente3!H6,Quest.Utente4!H6) -> 3.25
A7: T1_KS2_Creazione | B7: Sai distinguere tra le diverse categorie di interessi messe a disposizione dall'app? | C7: =AVERAGE(Quest.Utente1!H7,Quest.Utente2!H7,Quest.Utente3!H7,Quest.Utente4!H7) -> 2.75
A8: T1_KS3_Creazione | B8: Conosci la differenza tra inserire un interesse generico e uno specifico in questa fase? | C8: =AVERAGE(Quest.Utente1!H8,Quest.Utente2!H8,Quest.Utente3!H8,Quest.Utente4!H8) -> 3
B9: Personal Control
A10: T1_PC1_Creazione | B10: Senti di poter decidere liberamente quali aspetti della tua vita privata omettere dal diario? | C10: =AVERAGE(Quest.Utente1!H10,Quest.Utente2!H10,Quest.Utente3!H10,Quest.Utente4!H10) -> 3.5
A11: T1_PC2_Creazione | B11: Ti senti padrone della scelta di quanto tempo dedicare a questa configurazione iniziale? | C11: =AVERAGE(Quest.Utente1!H11,Quest.Utente2!H11,Quest.Utente3!H11,Quest.Utente4!H11) -> 4.75
B12: Motivation
A13: T1_MOT1_Creazione | B13: Quanto ti stimola l'idea che, compilando il diario, l'app diventerà uno specchio dei tuoi gusti? | C13: =AVERAGE(Quest.Utente1!H13,Quest.Utente2!H13,Quest.Utente3!H13,Quest.Utente4!H13) -> 4
A14: T1_MOT1_Creazione | B14: Sei spinto a inserire più dettagli possibili per ottenere suggerimenti di alta qualità? | C14: =AVERAGE(Quest.Utente1!H14,Quest.Utente2!H14,Quest.Utente3!H14,Quest.Utente4!H14) -> 3.25
B15: Self Efficacy
A16: T2_SE1_Aggiornamento | B16: Quanto ti senti sicuro di poter modificare i tuoi orari quando il tuo stile di vita cambia? | C16: =AVERAGE(Quest.Utente1!H16,Quest.Utente2!H16,Quest.Utente3!H16,Quest.Utente4!H16) -> 3.25
A17: T2_SE2_Aggiornamento | B17: Ti senti in grado di eliminare un vecchio interesse che non ti appartiene più in pochi secondi? | C17: =AVERAGE(Quest.Utente1!H17,Quest.Utente2!H17,Quest.Utente3!H17,Quest.Utente4!H17) -> 2
A18: T2_SE3_Aggiornamento | B18: Sei certo di riuscire a mantenere il diario aggiornato anche se hai poco tempo a disposizione? | C18: =AVERAGE(Quest.Utente1!H18,Quest.Utente2!H18,Quest.Utente3!H18,Quest.Utente4!H18) -> 3.5
B19: Knowledge&Skills
A20: T2_KS1_Aggiornamento | B20: Sai in quale sezione del profilo devi recarti per modificare la tua disponibilità settimanale? | C20: =AVERAGE(Quest.Utente1!H20,Quest.Utente2!H20,Quest.Utente3!H20,Quest.Utente4!H20) -> 2.5
A21: T2_KS2_Aggiornamento | B21: Hai compreso come le modifiche che apporti oggi influenzeranno i suggerimenti di domani? | C21: =AVERAGE(Quest.Utente1!H21,Quest.Utente2!H21,Quest.Utente3!H21,Quest.Utente4!H21) -> 4
A22: T2_KS3_Aggiornamento | B22: Conosci la procedura per salvare correttamente i cambiamenti apportati alle preferenze? | C22: =AVERAGE(Quest.Utente1!H22,Quest.Utente2!H22,Quest.Utente3!H22,Quest.Utente4!H22) -> 4
B23: Personal Control
A24: T2_PC1_Aggiornamento | B24: Senti di avere il controllo totale sulla frequenza con cui puoi cambiare i tuoi dati? | C24: =AVERAGE(Quest.Utente1!H24,Quest.Utente2!H24,Quest.Utente3!H24,Quest.Utente4!H24) -> 3.25
A25: T2_PC2_Aggiornamento | B25: Ti senti libero di resettare completamente le tue preferenze se decidi di cambiare interessi? | C25: =AVERAGE(Quest.Utente1!H25,Quest.Utente2!H25,Quest.Utente3!H25,Quest.Utente4!H25) -> 2
B26: Self Efficacy
A27: T3_SE1_Visualizzazione | B27: Quanto ti senti capace di individuare rapidamente l'evento perfetto tra quelli proposti? | C27: =AVERAGE(Quest.Utente1!H27,Quest.Utente2!H27,Quest.Utente3!H27,Quest.Utente4!H27) -> 2.75
A28: T3_SE2_Visualizzazione | B28: Sei sicuro di saper navigare tra i vari suggerimenti senza sentirti sopraffatto? | C28: =AVERAGE(Quest.Utente1!H28,Quest.Utente2!H28,Quest.Utente3!H28,Quest.Utente4!H28) -> 2.5
A29: T3_SE3_Visualizzazione | B29: Ti senti in grado di interpretare correttamente i simboli che indicano la compatibilità con i tuoi gusti? | C29: =AVERAGE(Quest.Utente1!H29,Quest.Utente2!H29,Quest.Utente3!H29,Quest.Utente4!H29) -> 3.25
B30: Knowledge&Skills
A31: T3_KS1_Visualizzazione | B31: Sai come vengono ordinati i suggerimenti che vedi sulla schermata principale? | C31: =AVERAGE(Quest.Utente1!H31,Quest.Utente2!H31,Quest.Utente3!H31,Quest.Utente4!H31) -> 3.25
A32: T3_KS2_Visualizzazione | B32: Hai capito perché alcuni eventi appaiono come "prioritari" rispetto ad altri? | C32: =AVERAGE(Quest.Utente1!H32,Quest.Utente2!H32,Quest.Utente3!H32,Quest.Utente4!H32) -> 2
A33: T3_KS3_Visualizzazione | B33: Conosci il significato dei tag di categorizzazione associati a ogni suggerimento? | C33: =AVERAGE(Quest.Utente1!H33,Quest.Utente2!H33,Quest.Utente3!H33,Quest.Utente4!H33) -> 3.25
B34: Motivation
A35: T3_MOT1_Visualizzazione | B35: Quanto ti entusiasma scoprire attività nuove che non avresti mai cercato da solo? | C35: =AVERAGE(Quest.Utente1!H35,Quest.Utente2!H35,Quest.Utente3!H35,Quest.Utente4!H35) -> 5
A36: T3_MOT1_Visualizzazione | B36: Ti senti spronato a usare l'app ogni mattina per vedere cosa ha selezionato per te? | C36: =AVERAGE(Quest.Utente1!H36,Quest.Utente2!H36,Quest.Utente3!H36,Quest.Utente4!H36) -> 3.75
B37: Self Efficacy
A38: T4_SE1_Analisi | B38: Quanto ti senti sicuro nel valutare se un evento è raggiungibile in tempo basandoti sulla distanza indicata? | C38: =AVERAGE(Quest.Utente1!H38,Quest.Utente2!H38,Quest.Utente3!H38,Quest.Utente4!H38) -> 4.25
A39: T4_SE2_Analisi | B39: Ti senti in grado di capire se un evento è adatto al tuo budget leggendo i dettagli? | C39: =AVERAGE(Quest.Utente1!H39,Quest.Utente2!H39,Quest.Utente3!H39,Quest.Utente4!H39) -> 3.5
A40: T4_SE3_Analisi | B40: Sei certo di poter decidere se partecipare a un evento dopo aver letto la sua descrizione tecnica? | C40: =AVERAGE(Quest.Utente1!H40,Quest.Utente2!H40,Quest.Utente3!H40,Quest.Utente4!H40) -> 4.5
...

Sheet TabRisultati
A1: Task | B1: ISE | C1: IKS | D1: IPC | E1: IMOT
A2: T1 | B2: =AVERAGE(MEDIE!C2:C4) -> 3.3333333 | C2: =AVERAGE(MEDIE!C6:C8) -> 3 | D2: =AVERAGE(MEDIE!C10:C11) -> 4.125 | E2: =AVERAGE(MEDIE!C13:C14) -> 3.625
A3: T2 | B3: =AVERAGE(MEDIE!C17) -> 2 | C3: =AVERAGE(MEDIE!C20:C22) -> 3.5 | D3: =AVERAGE(MEDIE!C24:C25) -> 2.625 | E3: N/A
A4: T3 | B4: =AVERAGE(MEDIE!C27:C29) -> 2.8333333 | C4: =AVERAGE(MEDIE!C31:C33) -> 2.8333333 | D4: N/A | E4: =AVERAGE(MEDIE!C35:C36) -> 4.375
A5: T4 | B5: =AVERAGE(MEDIE!C38:C40) -> 4.0833333 | C5: =AVERAGE(MEDIE!C42:C44) -> 2.75 | D5: N/A | E5: =AVERAGE(MEDIE!C46:C47) -> 3.875
A6: T5 | B6: =AVERAGE(MEDIE!C49:C51) -> 3.6666667 | C6: =AVERAGE(MEDIE!C53:C55) -> 3 | D6: =AVERAGE(MEDIE!C57:C58) -> 3.125 | E6: =AVERAGE(MEDIE!C60:C61) -> 4
A7: T6 | B7: =AVERAGE(MEDIE!C63:C65) -> 3.1666667 | C7: N/A | D7: =AVERAGE(MEDIE!C67:C68) -> 3.75 | E7: =AVERAGE(MEDIE!C70:C71) -> 3.625
A8: T7 | B8: =AVERAGE(MEDIE!C73:C75) -> 3.25 | C8: =AVERAGE(MEDIE!C77:C79) -> 3.0833333 | D8: =AVERAGE(MEDIE!C82:C83) -> 4.25 | E8: =AVERAGE(MEDIE!C84:C85) -> 3.5
A9: T8 | B9: =AVERAGE(MEDIE!C87:C89) -> 3.25 | C9: N/A | D9: =AVERAGE(MEDIE!C91:C92) -> 3.5 | E9: =AVERAGE(MEDIE!C94:C95) -> 3.375
